<?xml version="1.0" encoding="utf-8"?>
<!-- =================================================================================== -->
<!-- |    This document was autogenerated by xacro from grid_arm_full_24.xacro         | -->
<!-- |    EDITING THIS FILE BY HAND IS NOT RECOMMENDED                                 | -->
<!-- =================================================================================== -->
<robot name="grid_arm">
  <gazebo>
    <plugin filename="libgazebo_ros_control.so" name="gazebo_ros_control">
      <robotNamespace>/grid</robotNamespace>
    </plugin>
  </gazebo>
  <transmission name="tran1">
    <type>transmission_interface/SimpleTransmission</type>
    <joint name="joint_fixed_base__x_plotter">
      <hardwareInterface>hardware_interface/PositionJointInterface</hardwareInterface>
    </joint>
    <actuator name="motor1">
      <hardwareInterface>hardware_interface/PositionJointInterface</hardwareInterface>
      <mechanicalReduction>1</mechanicalReduction>
    </actuator>
  </transmission>
  <transmission name="tran1">
    <type>transmission_interface/SimpleTransmission</type>
    <joint name="joint_x_plotter__y_plotter">
      <hardwareInterface>hardware_interface/PositionJointInterface</hardwareInterface>
    </joint>
    <actuator name="motor1">
      <hardwareInterface>hardware_interface/PositionJointInterface</hardwareInterface>
      <mechanicalReduction>1</mechanicalReduction>
    </actuator>
  </transmission>
  <transmission name="tran1">
    <type>transmission_interface/SimpleTransmission</type>
    <joint name="joint_y_plotter__z_plotter">
      <hardwareInterface>hardware_interface/PositionJointInterface</hardwareInterface>
    </joint>
    <actuator name="motor1">
      <hardwareInterface>hardware_interface/PositionJointInterface</hardwareInterface>
      <mechanicalReduction>1</mechanicalReduction>
    </actuator>
  </transmission>
  <transmission name="tran1">
    <type>transmission_interface/SimpleTransmission</type>
    <joint name="joint_TR__RR">
      <hardwareInterface>hardware_interface/PositionJointInterface</hardwareInterface>
    </joint>
    <actuator name="motor1">
      <hardwareInterface>hardware_interface/PositionJointInterface</hardwareInterface>
      <mechanicalReduction>1</mechanicalReduction>
    </actuator>
  </transmission>
  <transmission name="tran1">
    <type>transmission_interface/SimpleTransmission</type>
    <joint name="joint_z_plotter__TR">
      <hardwareInterface>hardware_interface/PositionJointInterface</hardwareInterface>
    </joint>
    <actuator name="motor1">
      <hardwareInterface>hardware_interface/PositionJointInterface</hardwareInterface>
      <mechanicalReduction>1</mechanicalReduction>
    </actuator>
  </transmission>
  <transmission name="tran1">
    <type>transmission_interface/SimpleTransmission</type>
    <joint name="joint_RR__GR">
      <hardwareInterface>hardware_interface/PositionJointInterface</hardwareInterface>
    </joint>
    <actuator name="motor1">
      <hardwareInterface>hardware_interface/PositionJointInterface</hardwareInterface>
      <mechanicalReduction>1</mechanicalReduction>
    </actuator>
  </transmission>
  <transmission name="tran1">
    <type>transmission_interface/SimpleTransmission</type>
    <joint name="joint_gripper_base__gripper_gear_r">
      <hardwareInterface>hardware_interface/PositionJointInterface</hardwareInterface>
    </joint>
    <actuator name="motor1">
      <hardwareInterface>hardware_interface/PositionJointInterface</hardwareInterface>
      <mechanicalReduction>1</mechanicalReduction>
    </actuator>
  </transmission>
  <transmission name="tran1">
    <type>transmission_interface/SimpleTransmission</type>
    <joint name="joint_gripper_gear_r__gripper_main_r_front">
      <hardwareInterface>hardware_interface/PositionJointInterface</hardwareInterface>
    </joint>
    <actuator name="motor1">
      <hardwareInterface>hardware_interface/PositionJointInterface</hardwareInterface>
      <mechanicalReduction>1</mechanicalReduction>
    </actuator>
  </transmission>
  <transmission name="tran1">
    <type>transmission_interface/SimpleTransmission</type>
    <joint name="joint_gripper_gear_r__gripper_main_r_back">
      <hardwareInterface>hardware_interface/PositionJointInterface</hardwareInterface>
    </joint>
    <actuator name="motor1">
      <hardwareInterface>hardware_interface/PositionJointInterface</hardwareInterface>
      <mechanicalReduction>1</mechanicalReduction>
    </actuator>
  </transmission>
  <transmission name="tran1">
    <type>transmission_interface/SimpleTransmission</type>
    <joint name="joint_gripper_base__gripper_gear_l">
      <hardwareInterface>hardware_interface/PositionJointInterface</hardwareInterface>
    </joint>
    <actuator name="motor1">
      <hardwareInterface>hardware_interface/PositionJointInterface</hardwareInterface>
      <mechanicalReduction>1</mechanicalReduction>
    </actuator>
  </transmission>
  <transmission name="tran1">
    <type>transmission_interface/SimpleTransmission</type>
    <joint name="joint_gripper_gear_l__gripper_main_l">
      <hardwareInterface>hardware_interface/PositionJointInterface</hardwareInterface>
    </joint>
    <actuator name="motor1">
      <hardwareInterface>hardware_interface/PositionJointInterface</hardwareInterface>
      <mechanicalReduction>1</mechanicalReduction>
    </actuator>
  </transmission>
  <transmission name="tran1">
    <type>transmission_interface/SimpleTransmission</type>
    <joint name="joint_gripper_base__gripper_support_l">
      <hardwareInterface>hardware_interface/PositionJointInterface</hardwareInterface>
    </joint>
    <actuator name="motor1">
      <hardwareInterface>hardware_interface/PositionJointInterface</hardwareInterface>
      <mechanicalReduction>1</mechanicalReduction>
    </actuator>
  </transmission>
  <transmission name="tran1">
    <type>transmission_interface/SimpleTransmission</type>
    <joint name="joint_gripper_base__gripper_support_r">
      <hardwareInterface>hardware_interface/PositionJointInterface</hardwareInterface>
    </joint>
    <actuator name="motor1">
      <hardwareInterface>hardware_interface/PositionJointInterface</hardwareInterface>
      <mechanicalReduction>1</mechanicalReduction>
    </actuator>
  </transmission>
  <!-- World Link -->
  <link name="world"/>
  <!-- Dummy Link -->
  <link name="link0"/>
  <joint name="world_joint" type="fixed">
    <parent link="world"/>
    <child link="link0"/>
    <origin rpy="0 0 0" xyz="0 0 0"/>
    <axis xyz="0 0 1"/>
  </joint>
  <!-- First Robot -->
  <joint name="link0_joint" type="fixed">
    <parent link="link0"/>
    <child link="fixed_base"/>
    <origin rpy="0 0 0" xyz="0 -0.5 0"/>
  </joint>
  <link name="fixed_base">
    <inertial>
      <origin rpy="0 0 0" xyz="-0.0165417490096955 -6.57993949222385E-12 1.14629145643741"/>
      <mass value="902.749607650853"/>
      <inertia ixx="442.343035952779" ixy="1.02561691555876E-08" ixz="-1.68897306582117E-05" iyy="441.522969318833" iyz="-2.44220371471883E-11" izz="353.223581151376"/>
    </inertial>
    <visual>
      <origin rpy="0 0 0" xyz="0 0 0"/>
      <geometry>
        <mesh filename="package://grid_arm_full_24/meshes/fixed_base.STL"/>
      </geometry>
    </visual>
    <collision>
      <origin rpy="0 0 0" xyz="0 0 0"/>
      <geometry>
        <mesh filename="package://grid_arm_full_24/meshes/fixed_base.STL"/>
      </geometry>
    </collision>
  </link>
  <gazebo reference="fixed_base">
    <material>Gazebo/PaintedWall</material>
  </gazebo>
  <link name="link_x_plotter">
    <inertial>
      <origin rpy="0 0 0" xyz="0.000573351512093201 -0.0389473858648448 -1.97686156333532E-09"/>
      <mass value="30.11229972925189"/>
      <inertia ixx="10.00113173839496761" ixy="1.91839263060701E-05" ixz="-1.16492969765146E-08" iyy="30.08817810687703" iyz="-6.61441709127587E-11" izz="30.08751354137889"/>
    </inertial>
    <visual>
      <origin rpy="0 0 0" xyz="0 0 0"/>
      <geometry>
        <mesh filename="package://grid_arm_full_24/meshes/link_x_plotter.STL"/>
      </geometry>
      <material name="">
        <color rgba="0.898039215686275 0.917647058823529 0.929411764705882 1"/>
      </material>
    </visual>
    <collision>
      <origin rpy="0 0 0" xyz="0 0 0"/>
      <geometry>
        <mesh filename="package://grid_arm_full_24/meshes/link_x_plotter.STL"/>
      </geometry>
    </collision>
  </link>
  <joint name="joint_fixed_base__x_plotter" type="prismatic">
    <origin rpy="1.5707963267949 0 -1.57079632679489" xyz="1.95999999999999 0 2.801"/>
    <parent link="fixed_base"/>
    <child link="link_x_plotter"/>
    <axis xyz="0 0 1"/>
    <limit effort="4" lower="0" upper="3.92" velocity="4"/>
  </joint>
  <link name="link_y_plotter">
    <inertial>
      <origin rpy="0 0 0" xyz="-2.26007982202404E-07 -0.00581793826092114 0.590630146791493"/>
      <mass value="3.60938628880443"/>
      <inertia ixx="0.579879598478245" ixy="4.18804921462028E-08" ixz="4.93812706286357E-07" iyy="0.579611991847171" iyz="-0.00159234862404726" izz="0.0128116076219786"/>
    </inertial>
    <visual>
      <origin rpy="0 0 0" xyz="0 0 0"/>
      <geometry>
        <mesh filename="package://grid_arm_full_24/meshes/link_y_plotter.STL"/>
      </geometry>
      <material name="">
        <color rgba="0.792156862745098 0.819607843137255 0.933333333333333 1"/>
      </material>
    </visual>
    <collision>
      <origin rpy="0 0 0" xyz="0 0 0"/>
      <geometry>
        <mesh filename="package://grid_arm_full_24/meshes/link_y_plotter.STL"/>
      </geometry>
    </collision>
  </link>
  <joint name="joint_x_plotter__y_plotter" type="prismatic">
    <origin rpy="1.57079632679489 0 0" xyz="0 -0.00999999999999979 0"/>
    <parent link="link_x_plotter"/>
    <child link="link_y_plotter"/>
    <axis xyz="1 0 0"/>
    <limit effort="4" lower="-0.905" upper="0.905" velocity="4"/>
  </joint>
  <link name="link_z_plotter">
    <inertial>
      <origin rpy="0 0 0" xyz="0.108679550658774 4.33481210327027E-06 0.691064357686954"/>
      <mass value="1.94520500528742"/>
      <inertia ixx="0.01501193936489504" ixy="3.50050444624492E-10" ixz="0.00108805182461438" iyy="0.0133878998434258" iyz="4.50530989305055E-09" izz="0.0064231196735915"/>
    </inertial>
    <visual>
      <origin rpy="0 0 0" xyz="0 0 0"/>
      <geometry>
        <mesh filename="package://grid_arm_full_24/meshes/link_z_plotter.STL"/>
      </geometry>
      <material name="">
        <color rgba="0.647058823529412 0.619607843137255 0.584313725490196 1"/>
      </material>
    </visual>
    <collision>
      <origin rpy="0 0 0" xyz="0 0 0"/>
      <geometry>
        <mesh filename="package://grid_arm_full_24/meshes/link_z_plotter.STL"/>
      </geometry>
    </collision>
  </link>
  <joint name="joint_y_plotter__z_plotter" type="prismatic">
    <origin rpy="3.14159265358979 0 1.5707963267949" xyz="0 0.00661767556702997 1.285"/>
    <parent link="link_y_plotter"/>
    <child link="link_z_plotter"/>
    <axis xyz="0 0 -1"/>
    <limit effort="50" lower="0" upper="1.1" velocity="4"/>
  </joint>
  <link name="link_TR">
    <inertial>
      <origin rpy="0 0 0" xyz="-4.70734562441066E-14 -0.00114853821208827 -0.129212941334637"/>
      <mass value="0.360747325905685"/>
      <inertia ixx="0.00335468725474561" ixy="4.11080922882319E-19" ixz="1.22968080396599E-17" iyy="0.00338903649550634" iyz="-4.40381390197941E-05" izz="0.00022172684934952"/>
    </inertial>
    <visual>
      <origin rpy="0 0 0" xyz="0 0 0"/>
      <geometry>
        <mesh filename="package://grid_arm_full_24/meshes/link_TR.STL"/>
      </geometry>
      <material name="">
        <color rgba="1 1 1 1"/>
      </material>
    </visual>
    <collision>
      <origin rpy="0 0 0" xyz="0 0 0"/>
      <geometry>
        <mesh filename="package://grid_arm_full_24/meshes/link_TR.STL"/>
      </geometry>
    </collision>
  </link>
  <joint name="joint_z_plotter__TR" type="revolute">
    <origin rpy="0 0 3.14159265358979" xyz="0.167704601560146 0 0.380999999999992"/>
    <parent link="link_z_plotter"/>
    <child link="link_TR"/>
    <axis xyz="0 0 1"/>
    <limit effort="4" lower="-3.14" upper="3.14" velocity="4"/>
  </joint>
  <link name="link_RR">
    <inertial>
      <origin rpy="0 0 0" xyz="0.107927487593133 3.11245806905447E-08 -0.0308237948924113"/>
      <mass value="0.763031363649531"/>
      <inertia ixx="0.00118067572053214" ixy="4.15220906743451E-09" ixz="1.78845644612539E-05" iyy="0.00650329106268063" iyz="1.51725369572691E-11" izz="0.00631146042518126"/>
    </inertial>
    <visual>
      <origin rpy="0 0 0" xyz="0 0 0"/>
      <geometry>
        <mesh filename="package://grid_arm_full_24/meshes/link_RR.STL"/>
      </geometry>
      <material name="">
        <color rgba="1 1 1 1"/>
      </material>
    </visual>
    <collision>
      <origin rpy="0 0 0" xyz="0 0 0"/>
      <geometry>
        <mesh filename="package://grid_arm_full_24/meshes/link_RR.STL"/>
      </geometry>
    </collision>
  </link>
  <joint name="joint_TR__RR" type="revolute">
    <origin rpy="1.5707963267949 1.5707963267949 0" xyz="0 -0.0150000000000452 -0.235499999999993"/>
    <parent link="link_TR"/>
    <child link="link_RR"/>
    <axis xyz="0 0 1"/>
    <limit effort="4" lower="-3.14" upper="3.14" velocity="4"/>
  </joint>
  <link name="link_GR">
    <inertial>
      <origin rpy="0 0 0" xyz="0.0389999503182779 2.55351295663786E-14 0.00735114113255013"/>
      <mass value="0.081487076801313"/>
      <inertia ixx="3.20404991697089E-05" ixy="4.1894954021811E-19" ixz="-1.93018601491982E-05" iyy="0.000115082205931303" iyz="1.03575594944119E-19" izz="0.000107569340573337"/>
    </inertial>
    <visual>
      <origin rpy="0 0 0" xyz="0 0 0"/>
      <geometry>
        <mesh filename="package://grid_arm_full_24/meshes/link_GR.STL"/>
      </geometry>
      <material name="">
        <color rgba="1 1 1 1"/>
      </material>
    </visual>
    <collision>
      <origin rpy="0 0 0" xyz="0 0 0"/>
      <geometry>
        <mesh filename="package://grid_arm_full_24/meshes/link_GR.STL"/>
      </geometry>
    </collision>
  </link>
  <joint name="joint_RR__GR" type="revolute">
    <origin rpy="0 0 0" xyz="0.2175 0 0"/>
    <parent link="link_RR"/>
    <child link="link_GR"/>
    <axis xyz="0 0 -1"/>
    <limit effort="4" lower="-3.14" upper="3.14" velocity="4"/>
  </joint>
  <link name="link_gripper_base">
    <inertial>
      <origin rpy="0 0 0" xyz="-0.00296356692678401 0.00699027207260368 -0.0383865349138777"/>
      <mass value="0.160839094510415"/>
      <inertia ixx="0.000437844785715729" ixy="7.68847378226467E-06" ixz="8.80092772755738E-07" iyy="0.000290344234650636" iyz="-6.39829146841089E-07" izz="0.000164972035155789"/>
    </inertial>
    <visual>
      <origin rpy="0 0 0" xyz="0 0 0"/>
      <geometry>
        <mesh filename="package://grid_arm_full_24/meshes/link_gripper_base.STL"/>
      </geometry>
      <material name="">
        <color rgba="1 1 1 1"/>
      </material>
    </visual>
    <collision>
      <origin rpy="0 0 0" xyz="0 0 0"/>
      <geometry>
        <mesh filename="package://grid_arm_full_24/meshes/link_gripper_base.STL"/>
      </geometry>
    </collision>
  </link>
  <joint name="joint_GR__gripper_base" type="fixed">
    <origin rpy="1.5707963267949 0 -1.57079632679489" xyz="0.105 -0.00400058714716089 0.000978075898152433"/>
    <parent link="link_GR"/>
    <child link="link_gripper_base"/>
    <axis xyz="0 0 0"/>
  </joint>
  <link name="link_gripper_gear_r">
    <inertial>
      <origin rpy="0 0 0" xyz="0.0241992598155204 9.03959297215984E-06 -0.0180000000000269"/>
      <mass value="0.255661288466245"/>
      <inertia ixx="0.000106158861765566" ixy="-9.53765788329669E-08" ixz="6.98700784702463E-20" iyy="0.000509198073218786" iyz="-3.61973685777237E-20" izz="0.000560134096675643"/>
    </inertial>
    <visual>
      <origin rpy="0 0 0" xyz="0 0 0"/>
      <geometry>
        <mesh filename="package://grid_arm_full_24/meshes/link_gripper_gear_r.STL"/>
      </geometry>
      <material name="">
        <color rgba="1 1 1 1"/>
      </material>
    </visual>
    <collision>
      <origin rpy="0 0 0" xyz="0 0 0"/>
      <geometry>
        <mesh filename="package://grid_arm_full_24/meshes/link_gripper_gear_r.STL"/>
      </geometry>
    </collision>
  </link>
  <joint name="joint_gripper_base__gripper_gear_r" type="revolute">
    <origin rpy="-1.57079632679489 -0.00892723464357082 -1.5707963267949" xyz="-0.0089999999999999 -0.0271064972577203 -0.0489589803375026"/>
    <parent link="link_gripper_base"/>
    <child link="link_gripper_gear_r"/>
    <axis xyz="0 0 -1"/>
    <limit effort="4" lower="-3.14" upper="3.14" velocity="4"/>
  </joint>
  <link name="link_gripper_main_r_front">
    <inertial>
      <origin rpy="0 0 0" xyz="-0.0806701711106237 0.0135395802789818 -0.0127500677743388"/>
      <mass value="0.148646830972698"/>
      <inertia ixx="4.53782473245455E-05" ixy="9.25549070467646E-05" ixz="-1.60964054791292E-09" iyy="0.000395541950088996" iyz="-3.08233803483036E-09" izz="0.000424810624079809"/>
    </inertial>
    <visual>
      <origin rpy="0 0 0" xyz="0 0 0"/>
      <geometry>
        <mesh filename="package://grid_arm_full_24/meshes/link_gripper_main_r_front.STL"/>
      </geometry>
      <material name="">
        <color rgba="1 1 1 1"/>
      </material>
    </visual>
    <collision>
      <origin rpy="0 0 0" xyz="0 0 0"/>
      <geometry>
        <mesh filename="package://grid_arm_full_24/meshes/link_gripper_main_r_front.STL"/>
      </geometry>
    </collision>
  </link>
  <joint name="joint_gripper_gear_r__gripper_main_r_front" type="revolute">
    <origin rpy="0 0 -1.17425453204707" xyz="0.117951436434015 0 -0.036"/>
    <parent link="link_gripper_gear_r"/>
    <child link="link_gripper_main_r_front"/>
    <axis xyz="0 0 -1"/>
    <limit effort="4" lower="-3.14" upper="3.14" velocity="4"/>
  </joint>
  <link name="link_gripper_main_r_back">
    <inertial>
      <origin rpy="0 0 0" xyz="-0.0806701711106204 0.0135395802790023 0.012749932225661"/>
      <mass value="0.148646830972699"/>
      <inertia ixx="4.53782473245925E-05" ixy="9.25549070468535E-05" ixz="-1.60964054773562E-09" iyy="0.00039554195008895" iyz="-3.08233803479665E-09" izz="0.000424810624079811"/>
    </inertial>
    <visual>
      <origin rpy="0 0 0" xyz="0 0 0"/>
      <geometry>
        <mesh filename="package://grid_arm_full_24/meshes/link_gripper_main_r_back.STL"/>
      </geometry>
      <material name="">
        <color rgba="1 1 1 1"/>
      </material>
    </visual>
    <collision>
      <origin rpy="0 0 0" xyz="0 0 0"/>
      <geometry>
        <mesh filename="package://grid_arm_full_24/meshes/link_gripper_main_r_back.STL"/>
      </geometry>
    </collision>
  </link>


 <joint name="joint_gripper_gear_r__gripper_main_r_back" type="revolute">
    <origin rpy="0 0 -1.17425453204707" xyz="0.117951436434033 0 0"/>
    <parent link="link_gripper_gear_r"/>
    <child link="link_gripper_main_r_back"/>
    <axis xyz="0 0 -1"/>
    <limit effort="4" lower="-3.14" upper="3.14" velocity="4"/>
  </joint>
  <link name="link_gripper_gear_l">
    <inertial>
      <origin rpy="0 0 0" xyz="0.023926178552638 -2.25471863402049E-10 -0.00599999999997336"/>
      <mass value="0.0851552596784291"/>
      <inertia ixx="2.72075132297202E-05" ixy="1.28443547562495E-12" ixz="-1.13832820180159E-20" iyy="0.000159323879903172" iyz="2.06666742779727E-20" izz="0.00018448766690061"/>
    </inertial>
    <visual>
      <origin rpy="0 0 0" xyz="0 0 0"/>
      <geometry>
        <mesh filename="package://grid_arm_full_24/meshes/link_gripper_gear_l.STL"/>
      </geometry>
      <material name="">
        <color rgba="1 1 1 1"/>
      </material>
    </visual>
    <collision>
      <origin rpy="0 0 0" xyz="0 0 0"/>
      <geometry>
        <mesh filename="package://grid_arm_full_24/meshes/link_gripper_gear_l.STL"/>
      </geometry>
    </collision>
  </link>
  <joint name="joint_gripper_base__gripper_gear_l" type="revolute">
    <origin rpy="-1.5707963267949 -0.011381242593285 1.57079632679489" xyz="-0.0209999999999995 0.053000000000002 -0.0489589803375017"/>
    <parent link="link_gripper_base"/>
    <child link="link_gripper_gear_l"/>
    <axis xyz="0 0 -1"/>
    <limit effort="4" lower="-3.14" upper="3.14" velocity="4"/>
  </joint>
  <link name="link_gripper_main_l">
    <inertial>
      <origin rpy="0 0 0" xyz="0.0806701711127222 -0.0135395802836227 0.0127499322257154"/>
      <mass value="0.148646830981076"/>
      <inertia ixx="4.53782473133092E-05" ixy="9.25549071415814E-05" ixz="1.6096389040761E-09" iyy="0.000395541949984575" iyz="3.08233776646213E-09" izz="0.000424810623963608"/>
    </inertial>
    <visual>
      <origin rpy="0 0 0" xyz="0 0 0"/>
      <geometry>
        <mesh filename="package://grid_arm_full_24/meshes/link_gripper_main_l.STL"/>
      </geometry>
      <material name="">
        <color rgba="1 1 1 1"/>
      </material>
    </visual>
    <collision>
      <origin rpy="0 0 0" xyz="0 0 0"/>
      <geometry>
        <mesh filename="package://grid_arm_full_24/meshes/link_gripper_main_l.STL"/>
      </geometry>
    </collision>
  </link>
  <joint name="joint_gripper_gear_l__gripper_main_l" type="revolute">
    <origin rpy="0 0 1.96988805917067" xyz="0.11796 0 0"/>
    <parent link="link_gripper_gear_l"/>
    <child link="link_gripper_main_l"/>
    <axis xyz="0 0 -1"/>
    <limit effort="4" lower="-3.14" upper="3.14" velocity="4"/>
  </joint>
  <link name="link_gripper_support_l">
    <inertial>
      <origin rpy="0 0 0" xyz="-0.0585000000000479 3.5527136788005E-15 -0.00599999999997314"/>
      <mass value="0.0377874387363546"/>
      <inertia ixx="2.28794002198852E-06" ixy="-2.18590748673263E-20" ixz="-3.08709092987619E-21" iyy="5.48407859174781E-05" iyz="6.16078954177805E-21" izz="5.62218274097941E-05"/>
    </inertial>
    <visual>
      <origin rpy="0 0 0" xyz="0 0 0"/>
      <geometry>
        <mesh filename="package://grid_arm_full_24/meshes/link_gripper_support_l.STL"/>
      </geometry>
      <material name="">
        <color rgba="1 1 1 1"/>
      </material>
    </visual>
    <collision>
      <origin rpy="0 0 0" xyz="0 0 0"/>
      <geometry>
        <mesh filename="package://grid_arm_full_24/meshes/link_gripper_support_l.STL"/>
      </geometry>
    </collision>
  </link>
  <joint name="joint_gripper_base__gripper_support_l" type="revolute">
    <origin rpy="1.5707963267949 0.00206166895742368 -1.5707963267949" xyz="-0.020999999999999 0.0289999999999989 -0.108958980337504"/>
    <parent link="link_gripper_base"/>
    <child link="link_gripper_support_l"/>
    <axis xyz="0 0 -1"/>
    <limit effort="4" lower="-3.14" upper="3.14" velocity="4"/>
  </joint>
  <link name="link_gripper_support_r">
    <inertial>
      <origin rpy="0 0 0" xyz="0.0584999999999399 -1.99840144432528E-15 0.0180000000000264"/>
      <mass value="0.113362316209064"/>
      <inertia ixx="1.77466024220357E-05" ixy="1.96840605220804E-17" ixz="-1.45476055954566E-19" iyy="0.000175405140108504" iyz="1.97088842045622E-21" izz="0.000168665482229382"/>
    </inertial>
    <visual>
      <origin rpy="0 0 0" xyz="0 0 0"/>
      <geometry>
        <mesh filename="package://grid_arm_full_24/meshes/link_gripper_support_r.STL"/>
      </geometry>
      <material name="">
        <color rgba="1 1 1 1"/>
      </material>
    </visual>
    <collision>
      <origin rpy="0 0 0" xyz="0 0 0"/>
      <geometry>
        <mesh filename="package://grid_arm_full_24/meshes/link_gripper_support_r.STL"/>
      </geometry>
    </collision>
  </link>
  <joint name="joint_gripper_base__gripper_support_r" type="revolute">
    <origin rpy="1.5707963267949 0.000433457680080216 -1.5707963267949" xyz="-0.00899999999999923 -0.00310649725770096 -0.108958980337503"/>
    <parent link="link_gripper_base"/>
    <child link="link_gripper_support_r"/>
    <axis xyz="0 0 -1"/>
    <limit effort="4" lower="-3.14" upper="3.14" velocity="4"/>
  </joint>

    <link name="camera_link">
      <collision>
        <origin xyz="0 0 0" rpy="0 0 0" />
        <geometry>
          <mesh filename="package://grid_arm_full_24/meshes/sensors/kinect.dae"/>

        </geometry>
      </collision>

      <visual>
        <origin xyz="0 0 0" rpy="0 0 0" />
        <geometry>
          <mesh filename="package://grid_arm_full_24/meshes/sensors/kinect.dae"/>
        </geometry>
        <material name="grey">
            <color rgba="0.2 0.2 0.2 1.0"/>
        </material>
      </visual>


      <inertial>
        <mass value="0.001" />
        <origin xyz="0 0 0" rpy="0 0 0" />
        <inertia ixx="0.0001" ixy="0" ixz="0" iyy="0.0001" iyz="0" izz="0.0001" />
      </inertial>

    </link>

  <joint name="camera_joint" type="fixed">
      <parent link="link_y_plotter"/>
      <child link="camera_link"/>
      <origin rpy="0 -1.57 -1.57" xyz="0 0.3 0"/>
      <axis xyz="1 0 0" />
  </joint>
     <gazebo reference="camera_link">
      <sensor type="camera" name="camera_camera_sensor">
        <update_rate>20.0</update_rate>
        <camera name ="tesla">
          <horizontal_fov>1.047198</horizontal_fov>
          <image>
            <format>R8G8B8</format>
            <width>640</width>
            <height>480</height>
          </image>
          <clip>
            <near>0.05</near>
            <far>3</far>
          </clip>
        </camera>

        <plugin name="camera_camera_controller" filename="libgazebo_ros_camera.so">
          <alwaysOn>true</alwaysOn>
          <updateRate>0.0</updateRate>
          <cameraName>rgb/camera</cameraName>
          <imageTopicName>image_raw</imageTopicName>
          <cameraInfoTopicName>camera_info</cameraInfoTopicName>
          <frameName>camera_link</frameName>
          <hackBaseline>0.07</hackBaseline>
          <distortionK1>0.0</distortionK1>
          <distortionK2>0.0</distortionK2>
          <distortionK3>0.0</distortionK3>
          <distortionT1>0.0</distortionT1>
          <distortionT2>0.0</distortionT2>
        </plugin>
        
      </sensor>
    </gazebo> 

  <gazebo reference="camera_link">
  <sensor name="camera_link_camera" type="depth">
    <update_rate>20</update_rate>
    <camera>
      <horizontal_fov>1.047198</horizontal_fov>
      <image>
        <width>640</width>
        <height>480</height>
        <format>R8G8B8</format>
      </image>
      <clip>
        <near>0.05</near>
        <far>3</far>
      </clip>
    </camera>
    <plugin name="camera_link_controller" filename="libgazebo_ros_openni_kinect.so">
      <baseline>0.2</baseline>
      <alwaysOn>true</alwaysOn>
      <updateRate>0.0</updateRate>
      <cameraName>camera_ir</cameraName>
      <imageTopicName>/camera/color/image_raw</imageTopicName>
      <cameraInfoTopicName>/camera/color/camera_info</cameraInfoTopicName>
      <depthImageTopicName>/camera/depth/image_raw</depthImageTopicName>
      <depthImageInfoTopicName>/camera/depth/camera_info</depthImageInfoTopicName>
      <pointCloudTopicName>/camera//depth/points</pointCloudTopicName>
      <frameName>camera_link</frameName>
      <pointCloudCutoff>0.5</pointCloudCutoff>
      <pointCloudCutoffMax>3.0</pointCloudCutoffMax>
      <distortionK1>0.0</distortionK1>
      <distortionK2>0.0</distortionK2>
      <distortionK3>0.0</distortionK3>
      <distortionT1>0.0</distortionT1>
      <distortionT2>0.0</distortionT2>
      <CxPrime>0</CxPrime>
      <Cx>0</Cx>
      <Cy>0</Cy>
      <focalLength>0</focalLength>
      <hackBaseline>0</hackBaseline>
    </plugin>
  </sensor>
</gazebo>

<gazebo>
   <plugin name="gazebo_grasp_fix" filename="libgazebo_grasp_fix.so">
        <arm>
           <arm_name>grid_arm</arm_name>
           <palm_link>link_GR</palm_link>
           <gripper_link>link_gripper_main_l</gripper_link>
           <gripper_link>link_gripper_main_r_back</gripper_link>
           <gripper_link>link_gripper_main_r_front</gripper_link>
        </arm>
       <forces_angle_tolerance>90</forces_angle_tolerance>
       <update_rate>20</update_rate>
       <grip_count_threshold>4</grip_count_threshold>
       <max_grip_count>8</max_grip_count>
       <release_tolerance>0.05</release_tolerance>
       <disable_collisions_on_attach>true</disable_collisions_on_attach>
       <contact_topic>__default_topic__</contact_topic>
    </plugin>
</gazebo>

  <gazebo reference="link_gripper_main_l">
    <material>Gazebo/Grey</material>
    <implicitSpringDamper>1</implicitSpringDamper>
    <mu1>100000</mu1>
    <mu2>100000</mu2>
    <kp>100000000.0</kp>
    <kd>1.0</kd>
  </gazebo>
  <gazebo reference="link_gripper_main_r_back">
    <material>Gazebo/Grey</material>
    <implicitSpringDamper>1</implicitSpringDamper>
    <mu1>100000</mu1>
    <mu2>100000</mu2>
    <kp>100000000.0</kp>
    <kd>1.0</kd>
  </gazebo>
  <gazebo reference="link_gripper_main_r_front">
    <material>Gazebo/Grey</material>
    <implicitSpringDamper>1</implicitSpringDamper>
    <mu1>100000</mu1>
    <mu2>100000</mu2>
    <kp>100000000.0</kp>
    <kd>1.0</kd>
  </gazebo>
</robot>

